Workbook

Sheet LEIA-ME
A1: Painel de Processos — planilha de dados
A3: Esta planilha alimenta o Painel de Gestão de Processos da Codevasf. Cada aba vira uma tela do painel.
A4: Preencha as colunas em branco; o que estiver preenchido é dado de demonstração e pode ser substituído.
A6: Como preencher
A7: 1. Não renomeie abas nem cabeçalhos — o painel procura as colunas pelo nome exato.
A8: 2. Onde houver seta na célula, escolha um item da lista. Valor fora da lista é recusado.
A9: 3. Códigos ligam as abas: MP- macroprocesso · P- processo · SP- subprocesso · A- atividade · T- tarefa.
A10: 4. Datas no formato AAAA-MM-DD (ex.: 2026-05-29), como texto. Formate a coluna como Texto antes de digitar:
A11: o Excel converte 29/05/2026 em número de série.
A12: 5. Marcos M1 a M10 (aba Processos): Sim, Não ou Não se aplica.
A14: Colunas em CINZA: não digite
A15: Elas se calculam sozinhas a partir do que você já preencheu. Digitar por cima apaga a fórmula.
A16: Processos · Macroprocesso | B16: Vem do código do processo (P-06.01 → MP-06).
A17: Processos · Percentual | B17: Marcos "Sim" ÷ marcos aplicáveis. Os "Não se aplica" saem da conta.
A18: Documentos, Riscos e Indicadores · Vinculo_Nivel | B18: Vem do prefixo do código em Vinculo_Codigo.
A19: Riscos · Nivel_PxI | B19: Probabilidade × Impacto.
A20: Riscos · Classificacao | B20: Faixa do P×I: 20+ Extremo · 12+ Alto · 5+ Moderado · abaixo, Baixo.
A21: Indicadores · Situacao | B21: Compara Resultado com Meta, conforme a Polaridade.
A22: NUGEP · Unidade_Nome | B22: Vem da sigla, pela tabela de unidades na aba Listas (colunas V e W).
A24: Vínculo múltiplo: um documento, risco ou indicador pode apontar para mais de um item. Nesse caso,
A25: separe os códigos por ponto e vírgula em Vinculo_Codigo e escreva os níveis à mão em Vinculo_Nivel,
A26: na mesma ordem — a fórmula só resolve o vínculo único.
A28: O que cada aba alimenta
A29: Macroprocessos | B29: Cadeia de valor da tela inicial
A30: Processos | B30: Portfólio, fichas de processo e marcos do mapeamento
A31: Subprocessos / Atividades / Tarefas | B31: Hierarquia dentro da ficha do processo
A32: Documentos | B32: Aba Documentos publicados
A33: Riscos | B33: Radar de riscos e tabela de riscos
A34: Indicadores | B34: Painel de indicadores
A35: Jornada | B35: Wizard da jornada de mapeamento
A36: Repositorio | B36: Repositório de materiais
A37: NUGEP | B37: Equipe e contato institucional (Foto: URL da imagem; Hierarquia: 1 gerente-executivo, 2 gerente, 3 equipe, 0 interlocutor)
A38: Glossario | B38: Glossário
A39: FAQ | B39: Perguntas frequentes
A40: Parametros | B40: Textos e contatos que aparecem no painel (título da tela inicial, contato da unidade, links do rodapé)
A41: Listas | B41: Origem das listas suspensas e a tabela de unidades — não apague
A43: Dúvidas: ae.gpe.unp@codevasf.gov.br

Sheet Macroprocessos
A1: Codigo | B1: Nome | C1: Categoria | D1: Ordem | E1: Descricao | F1: Objetivo | G1: Unidade_Responsavel | H1: Dono_Processo | I1: Entregas | J1: Clientes_Beneficiarios | K1: Partes_Interessadas | L1: Sistemas | M1: Normativos_Aplicaveis | N1: Imagem_Bizagi | O1: Observacoes | P1: Unidades_Corresponsaveis
A2: MP-01 | B2: Gestão Estratégica e Governança | C2: Gerencial | D2: 1 | E2: Formulação, desdobramento e monitoramento da estratégia corporativa, da governança e do desempenho institucional. | F2: Garantir que a atuação da Companhia esteja alinhada à estratégia, com decisões baseadas em evidências. | G2: AE/GPE | H2: Gerente de Planejamento | I2: Plano Estratégico; Plano de Ação Anual; Relatórios de desempenho | J2: Diretoria Executiva; Conselho de Administração; Unidades internas | K2: Ministério supervisor; Órgãos de controle; Sociedade | L2: e-Codevasf; Painéis de BI | M2: Estatuto Social; Regimento Interno; Lei nº 13.303/2016 | P2: AR/GDT; AI/GOM
A3: MP-02 | B3: Gestão de Riscos, Integridade e Controles | C3: Gerencial | D3: 2 | E3: Identificação, avaliação e tratamento de riscos corporativos, integridade e controles internos (2ª linha). | F3: Assegurar razoável segurança para o alcance dos objetivos institucionais. | G3: AE/GAG | H3: Gerente de Governança | I3: Política de Gestão de Riscos; Matriz de riscos corporativa; Plano de integridade | J3: Alta administração; Gestores de 1ª linha | K3: Auditoria interna; CGU; TCU | L3: e-Codevasf; Sistema de gestão de riscos | M3: Política de Gestão de Riscos (fictícia); IN Conjunta MP/CGU nº 01/2016 | P3: AI/GOM; AR/GRB
A4: MP-03 | B4: Desenvolvimento Territorial e Estruturação Produtiva | C4: Finalístico | D4: 3 | E4: Apoio a arranjos produtivos, inclusão socioeconômica e estruturação de cadeias produtivas nos vales. | F4: Promover o desenvolvimento regional integrado e sustentável. | G4: AR/GDT | H4: Gerente de Desenvolvimento | I4: Projetos de estruturação produtiva; Convênios e instrumentos de repasse | J4: Produtores rurais; Cooperativas; Municípios | K4: Parlamentares; Entes federados; Entidades parceiras | L4: TransfereGov; e-Codevasf | M4: Lei nº 14.133/2021; Portarias de transferências voluntárias | P4: AR/GRB; AA/GLC
A5: MP-04 | B5: Gestão de Empreendimentos de Irrigação | C5: Finalístico | D5: 4 | E5: Implantação, operação, manutenção e transferência de gestão de perímetros públicos de irrigação. | F5: Ampliar a área irrigada produtiva com sustentabilidade hídrica e econômica. | G5: AI/GOM | H5: Gerente de Operação | I5: Perímetros em operação; Água distribuída; Relatórios de O&M | J5: Irrigantes; Distritos de irrigação | K5: ANA; Agências estaduais; Associações de usuários | L5: SIG-Irrigação (fictício); e-Codevasf | M5: Lei nº 12.787/2013 (Política Nacional de Irrigação) | P5: AA/GLC; AG/GGP
A6: MP-05 | B6: Revitalização de Bacias Hidrográficas | C6: Finalístico | D6: 5 | E6: Ações de recuperação hidroambiental, segurança hídrica e uso sustentável dos recursos naturais. | F6: Contribuir para a revitalização das bacias dos rios São Francisco e Parnaíba. | G6: AR/GRB | H6: Gerente de Revitalização | I6: Nascentes recuperadas; Obras hidroambientais; Sistemas de abastecimento | J6: Comunidades ribeirinhas; Municípios | K6: Comitês de bacia; MMA; Órgãos ambientais | L6: e-Codevasf; GeoPortal (fictício) | M6: Legislação ambiental aplicável | P6: AG/GGP; AT/GTI
A7: MP-06 | B7: Gestão de Licitações e Contratos | C7: Suporte | D7: 6 | E7: Planejamento das contratações, seleção de fornecedores e gestão dos contratos administrativos da Companhia. | F7: Prover contratações tempestivas, vantajosas e conformes à legislação. | G7: AA/GLC | H7: Gerente de Licitações | I7: Editais publicados; Contratos firmados; Atas de registro de preços | J7: Todas as unidades demandantes | K7: Fornecedores; Assessoria Jurídica; Órgãos de controle; PNCP | L7: Compras.gov.br; PNCP; Painel de Preços; e-Codevasf | M7: Lei nº 14.133/2021; Lei nº 13.303/2016; IN SEGES nº 65/2021; NI-027/2024 (fictícia) | O7: Macroprocesso priorizado no ciclo 2026 de mapeamento. | P7: AT/GTI; AE/GPE
A8: MP-07 | B8: Gestão de Pessoas | C8: Suporte | D8: 7 | E8: Provimento, desenvolvimento, remuneração e qualidade de vida do corpo funcional. | F8: Assegurar pessoas qualificadas e engajadas para a missão institucional. | G8: AG/GGP | H8: Gerente de Pessoas | I8: Empregados admitidos e capacitados; Folha de pagamento | J8: Empregados; Gestores | K8: Sindicatos; SEST; Ministério supervisor | L8: SIGEP (fictício); e-Codevasf | M8: CLT; Normas internas de pessoal | P8: AE/GPE; AE/GAG
A9: MP-08 | B9: Gestão de Tecnologia da Informação | C9: Suporte | D9: 8 | E9: Planejamento, desenvolvimento, sustentação e segurança dos serviços de TI. | F9: Prover soluções digitais seguras que habilitem os processos de negócio. | G9: AT/GTI | H9: Gerente de TI | I9: Sistemas em produção; Serviços de infraestrutura; Suporte ao usuário | J9: Todas as unidades | K9: SGD/MGI; Fornecedores de TI | L9: e-Codevasf; Service Desk | M9: IN SGD nº 94/2022; Política de Segurança da Informação (fictícia) | P9: AE/GAG; AR/GDT

Sheet Processos
A1: Codigo | B1: Macroprocesso | C1: Nome | D1: Descricao | E1: Objetivo | F1: Area_Responsavel | G1: Dono_Processo | H1: Interlocutor | I1: Prioridade | J1: Complexidade | K1: Status_Mapeamento | L1: Percentual | M1: Fase_Ciclo_BPM | N1: Inicio_Mapeamento | O1: Prazo_Previsto | P1: Data_Conclusao | Q1: Fornecedores | R1: Entradas | S1: Saidas | T1: Beneficiarios | U1: Sistemas | V1: Normativos_Relacionados | W1: Processo_ECodevasf | X1: Imagem_Bizagi | Y1: M1_Reuniao_Contextualizacao | Z1: M2_Macro_Processo_Modelados | AA1: M3_Subprocessos_Modelados | AB1: M4_ASIS_Modelado | AC1: M5_ASIS_Validado | AD1: M6_Procedimento_Validado | AE1: M7_Procedimento_Aprovado | AF1: M8_TOBE_Elaborado | AG1: M9_TOBE_Validado | AH1: M10_Publicado_Repositorio | AI1: Proxima_Acao | AJ1: Pendencia | AK1: Ultima_Atualizacao | AL1: Unidades_Corresponsaveis
A2: P-06.01 | B2: =IF(A2="","",IF(LEFT(A2,2)="P-","MP-"&MID(A2,3,2),"")) -> MP-06 | C2: Planejamento da Contratação | D2: Da identificação da necessidade (DFD) até a aprovação do ETP, TR e pesquisa de preços que instruem o certame. | E2: Instruir as contratações com estudos e artefatos completos, reduzindo retrabalho e impugnações. | F2: AA/GLC | G2: Gerente de Licitações | H2: Carlos Eduardo Lima (UNP) | I2: Alta | J2: Alta | K2: Concluído | L2: =IF(COUNTIF(Y2:AH2,"Sim")+COUNTIF(Y2:AH2,"Não")=0,"",ROUND(COUNTIF(Y2:AH2,"Sim")/(COUNTIF(Y2:AH2,"Sim")+COUNTIF(Y2:AH2,"Não")),4)) -> 1 | M2: 5. Medir o sucesso | N2: 2026-01-05 | O2: 2026-05-29 | P2: 2026-05-18 | Q2: Áreas demandantes; Painel de Preços; Fornecedores (cotações) | R2: DFD; Plano de Contratações Anual; Requisitos da área | S2: ETP aprovado; TR aprovado; Pesquisa de preços validada | T2: AA/GLC (Seleção do Fornecedor); Assessoria Jurídica | U2: e-Codevasf; Compras.gov.br; Painel de Preços | V2: Lei nº 14.133/2021; IN SEGES nº 65/2021; NI-027/2024 (fictícia) | W2: 59500.000123/2026-11 | X2: https://fluxosti.codevasf.gov.br/incidentes/ | Y2: Sim | Z2: Sim | AA2: Sim | AB2: Sim | AC2: Sim | AD2: Sim | AE2: Sim | AF2: Sim | AG2: Sim | AH2: Sim | AI2: Monitorar indicadores do processo e revisar o PRO em 12 meses. | AL2: AE/GAG; AR/GDT
A3: P-06.02 | B3: =IF(A3="","",IF(LEFT(A3,2)="P-","MP-"&MID(A3,3,2),"")) -> MP-06 | C3: Seleção do Fornecedor | D3: Da divulgação do edital à homologação do resultado, incluindo sessão pública, julgamento e recursos. | E3: Selecionar a proposta mais vantajosa com celeridade e segurança jurídica. | F3: AA/GLC | G3: Gerente de Licitações | H3: Carlos Eduardo Lima (UNP) | I3: Alta | J3: Média | K3: Em andamento | L3: =IF(COUNTIF(Y3:AH3,"Sim")+COUNTIF(Y3:AH3,"Não")=0,"",ROUND(COUNTIF(Y3:AH3,"Sim")/(COUNTIF(Y3:AH3,"Sim")+COUNTIF(Y3:AH3,"Não")),4)) -> 0.4 | M3: 2. Arquitetar mudanças | N3: 2026-06-01 | O3: 2026-09-30 | Q3: P-06.01 (artefatos); Compras.gov.br | R3: Edital minutado; Parecer jurídico; ETP/TR | S3: Resultado homologado; Contrato/ata para assinatura | T3: Unidades demandantes; Fornecedores | U3: Compras.gov.br; PNCP; e-Codevasf | V3: Lei nº 14.133/2021; NI-027/2024 (fictícia) | W3: 59500.000456/2026-22 | Y3: Sim | Z3: Sim | AA3: Sim | AB3: Sim | AC3: Não | AD3: Não | AE3: Não | AF3: Não | AG3: Não | AH3: Não | AI3: Validar AS-IS com o dono do processo (reunião marcada). | AJ3: Pendente retorno da área sobre fluxo de recursos administrativos. | AL3: AR/GDT; AI/GOM
A4: P-06.03 | B4: =IF(A4="","",IF(LEFT(A4,2)="P-","MP-"&MID(A4,3,2),"")) -> MP-06 | C4: Gestão e Fiscalização Contratual | D4: Da assinatura do contrato ao encerramento, incluindo fiscalização, medições, pagamentos e sanções. | E4: Garantir a entrega do objeto contratado no prazo, custo e qualidade pactuados. | F4: AA/GLC | G4: Gerente de Licitações | H4: Bruna Souza (UNP) | I4: Alta | J4: Alta | K4: Em andamento | L4: =IF(COUNTIF(Y4:AH4,"Sim")+COUNTIF(Y4:AH4,"Não")=0,"",ROUND(COUNTIF(Y4:AH4,"Sim")/(COUNTIF(Y4:AH4,"Sim")+COUNTIF(Y4:AH4,"Não")),4)) -> 0.2 | M4: 2. Arquitetar mudanças | N4: 2026-06-15 | O4: 2026-11-30 | Q4: P-06.02 (contrato); Fornecedores contratados | R4: Contrato assinado; Cronograma; Garantias | S4: Objeto recebido; Pagamentos efetuados; Termo de encerramento | T4: Unidades demandantes; Fornecedores | U4: e-Codevasf; Compras.gov.br | V4: Lei nº 14.133/2021; Manual de Fiscalização (fictício) | W4: 59500.000789/2026-33 | Y4: Sim | Z4: Sim | AA4: Não | AB4: Não | AC4: Não | AD4: Não | AE4: Não | AF4: Não | AG4: Não | AH4: Não | AI4: Concluir modelagem AS-IS das medições e pagamentos. | AL4: AI/GOM; AR/GRB
A5: P-04.01 | B5: =IF(A5="","",IF(LEFT(A5,2)="P-","MP-"&MID(A5,3,2),"")) -> MP-04 | C5: Operação e Manutenção de Perímetros Irrigados | D5: Programação e distribuição de água, manutenção da infraestrutura de uso comum e relacionamento com irrigantes. | E5: Assegurar a distribuição hídrica confiável e a conservação dos ativos. | F5: AI/GOM | G5: Gerente de Operação | H5: Eduardo Martins (UNP) | I5: Média | J5: Alta | K5: Em andamento | L5: =IF(COUNTIF(Y5:AH5,"Sim")+COUNTIF(Y5:AH5,"Não")=0,"",ROUND(COUNTIF(Y5:AH5,"Sim")/(COUNTIF(Y5:AH5,"Sim")+COUNTIF(Y5:AH5,"Não")),4)) -> 0.3 | M5: 2. Arquitetar mudanças | N5: 2026-05-04 | O5: 2026-10-30 | Q5: ANA (outorgas); Distritos de irrigação | R5: Outorga de uso; Demanda de irrigação; Plano de cultivo | S5: Água distribuída; Infraestrutura mantida; Relatórios de O&M | T5: Irrigantes; Distritos | U5: SIG-Irrigação (fictício); e-Codevasf | V5: Lei nº 12.787/2013 | W5: 59500.000901/2026-44 | Y5: Sim | Z5: Sim | AA5: Sim | AB5: Não | AC5: Não | AD5: Não | AE5: Não | AF5: Não | AG5: Não | AH5: Não | AI5: Agendar oficina de validação do AS-IS com o distrito. | AL5: AR/GRB; AA/GLC
A6: P-05.01 | B6: =IF(A6="","",IF(LEFT(A6,2)="P-","MP-"&MID(A6,3,2),"")) -> MP-05 | C6: Recuperação de Nascentes e Matas Ciliares | D6: Seleção de áreas, execução de cercamento e plantio, e monitoramento da regeneração. | E6: Recuperar áreas degradadas prioritárias das bacias. | F6: AR/GRB | G6: Gerente de Revitalização | H6: Eduardo Martins (UNP) | I6: Média | J6: Média | K6: Não iniciado | L6: =IF(COUNTIF(Y6:AH6,"Sim")+COUNTIF(Y6:AH6,"Não")=0,"",ROUND(COUNTIF(Y6:AH6,"Sim")/(COUNTIF(Y6:AH6,"Sim")+COUNTIF(Y6:AH6,"Não")),4)) -> 0 | M6: 1. Alinhamento à estratégia e metas | O6: 2027-03-31 | Q6: Municípios; Comitês de bacia | R6: Diagnóstico hidroambiental; Termos de cooperação | S6: Nascentes recuperadas; Relatórios de monitoramento | T6: Comunidades; Órgãos ambientais | U6: e-Codevasf; GeoPortal (fictício) | V6: Legislação ambiental aplicável | Y6: Não | Z6: Não | AA6: Não | AB6: Não | AC6: Não | AD6: Não | AE6: Não | AF6: Não | AG6: Não | AH6: Não | AI6: Enviar formulário de levantamento à área (previsto ago/2026). | AL6: AA/GLC; AG/GGP
A7: P-01.01 | B7: =IF(A7="","",IF(LEFT(A7,2)="P-","MP-"&MID(A7,3,2),"")) -> MP-01 | C7: Formulação e Monitoramento do Planejamento Estratégico | D7: Construção do plano estratégico, desdobramento em planos de ação e monitoramento periódico de resultados. | E7: Manter a estratégia viva, monitorada e comunicada. | F7: AE/GPE | G7: Gerente de Planejamento | H7: Gustavo Pereira (UNP) | I7: Alta | J7: Média | K7: Concluído | L7: =IF(COUNTIF(Y7:AH7,"Sim")+COUNTIF(Y7:AH7,"Não")=0,"",ROUND(COUNTIF(Y7:AH7,"Sim")/(COUNTIF(Y7:AH7,"Sim")+COUNTIF(Y7:AH7,"Não")),4)) -> 1 | M7: 5. Medir o sucesso | N7: 2025-09-01 | O7: 2026-02-27 | P7: 2026-02-20 | Q7: Diretoria; Unidades | R7: Diretrizes de governo; Diagnóstico institucional | S7: Plano Estratégico; Painel de indicadores; RAG | T7: Diretoria Executiva; Conselhos | U7: e-Codevasf; Painéis de BI | V7: Lei nº 13.303/2016 | W7: 59500.000015/2025-77 | Y7: Sim | Z7: Sim | AA7: Sim | AB7: Sim | AC7: Sim | AD7: Sim | AE7: Sim | AF7: Sim | AG7: Sim | AH7: Sim | AI7: Ciclo de monitoramento trimestral (próximo: set/2026). | AL7: AG/GGP; AT/GTI
A8: P-07.01 | B8: =IF(A8="","",IF(LEFT(A8,2)="P-","MP-"&MID(A8,3,2),"")) -> MP-07 | C8: Admissão e Integração de Empregados | D8: Da homologação do concurso à integração do novo empregado, incluindo exames, posse e ambientação. | E8: Admitir e integrar novos empregados com agilidade e conformidade. | F8: AG/GGP | G8: Gerente de Pessoas | H8: Bruna Souza (UNP) | I8: Baixa | J8: Baixa | K8: Não iniciado | L8: =IF(COUNTIF(Y8:AH8,"Sim")+COUNTIF(Y8:AH8,"Não")=0,"",ROUND(COUNTIF(Y8:AH8,"Sim")/(COUNTIF(Y8:AH8,"Sim")+COUNTIF(Y8:AH8,"Não")),4)) -> 0 | M8: 1. Alinhamento à estratégia e metas | O8: 2027-06-30 | Q8: Banca do concurso; Candidatos | R8: Resultado homologado; Documentação do candidato | S8: Empregado admitido e integrado | T8: Novos empregados; Unidades de lotação | U8: SIGEP (fictício); e-Codevasf | V8: CLT; Normas internas de pessoal | Y8: Não | Z8: Não | AA8: Não | AB8: Não | AC8: Não | AD8: Não | AE8: Não | AF8: Não | AG8: Não | AH8: Não | AI8: Aguardando priorização no ciclo 2027. | AL8: AT/GTI; AE/GPE

Sheet Subprocessos
A1: Codigo | B1: Vinculo_Pai | C1: Ordem | D1: Nome | E1: Descricao | F1: Objetivo | G1: Unidade_Responsavel | H1: Dono | I1: Entradas | J1: Saidas | K1: Sistemas | L1: Imagem_Bizagi | M1: Unidades_Corresponsaveis | N1: Reutilizavel | O1: Reutilizado_Em
A2: SP-06.01.01 | B2: P-06.01 | C2: 1 | D2: Estudo Técnico Preliminar (ETP) | E2: Caracterização da necessidade, análise de soluções de mercado e demonstração da viabilidade da contratação. | F2: Fundamentar tecnicamente a melhor solução para a necessidade. | G2: AA/GLC | H2: Gerente de Licitações | I2: DFD; Levantamento de soluções de mercado | J2: ETP aprovado no e-Codevasf | K2: e-Codevasf; Compras.gov.br | M2: AI/GOM
A3: SP-06.01.02 | B3: P-06.01 | C3: 2 | D3: Termo de Referência (TR) | E3: Definição do objeto, requisitos, modelo de execução e gestão contratual, e critérios de julgamento. | F3: Especificar com precisão o objeto e as condições da contratação. | G3: AA/GLC | H3: Gerente de Licitações | I3: ETP aprovado; Modelos padronizados de TR | J3: TR aprovado e validado juridicamente | K3: e-Codevasf | M3: AR/GRB
A4: SP-06.01.03 | B4: P-06.01 | C4: 3 | D4: Pesquisa de Preços | E4: Levantamento de preços em fontes admitidas (Painel de Preços, PNCP, cotações) e consolidação do valor estimado. | F4: Estimar o valor da contratação conforme a IN SEGES nº 65/2021. | G4: AA/GLC | H4: Gerente de Licitações | I4: TR validado; Fontes de preços admitidas | J4: Relatório de pesquisa de preços; Mapa comparativo | K4: Painel de Preços; PNCP; e-Codevasf | M4: AG/GGP
A5: SP-06.01.03.01 | B5: SP-06.01.03 | C5: 1 | D5: Tratamento de Preços Inexequíveis ou Excessivos | E5: Identificação e exclusão de valores discrepantes coletados na pesquisa, com justificativa técnica registrada. | F5: Evitar que outliers de preço distorçam o valor estimado da contratação. | G5: AA/GLC | H5: Gerente de Licitações | I5: Amostra de preços coletados na pesquisa | J5: Valores discrepantes identificados e justificados | K5: Planilha padrão; e-Codevasf | M5: AG/GGP | N5: Sim | O5: P-06.02; P-04.01
A6: SP-06.02.01 | B6: P-06.02 | C6: 1 | D6: Condução da Sessão Pública | E6: Abertura da sessão no sistema, fase de lances, julgamento, habilitação e registro em ata. | F6: Conduzir o certame com transparência e celeridade. | G6: AA/GLC | H6: Gerente de Licitações | I6: Edital publicado; Propostas dos licitantes | J6: Ata da sessão; Resultado por item | K6: Compras.gov.br | M6: AT/GTI
A7: SP-04.01.01 | B7: P-04.01 | C7: 1 | D7: Distribuição de Água aos Irrigantes | E7: Programação semanal, operação de comportas e bombas, e registro de volumes distribuídos. | F7: Entregar a água programada com eficiência e equidade. | G7: AI/GOM | H7: Gerente de Operação | I7: Outorga de uso; Demanda de irrigação | J7: Programação hídrica executada; Registros de volume | K7: SIG-Irrigação (fictício) | M7: AE/GPE

Sheet Atividades
A1: Codigo | B1: Vinculo_Pai | C1: Ordem | D1: Nome | E1: Descricao | F1: Responsavel_Ator | G1: Entradas | H1: Saidas | I1: Sistemas | J1: Base_Normativa | K1: Imagem_Bizagi | L1: Executor | M1: Unidades_Corresponsaveis | N1: Objetivo
A2: A-06.01.01.01 | B2: SP-06.01.01 | C2: 1 | D2: Formalizar a necessidade (DFD) | E2: Registrar o Documento de Formalização da Demanda com justificativa, quantitativos e alinhamento ao PCA. | F2: Área demandante | G2: Necessidade identificada; Plano de Contratações Anual | H2: DFD assinado no e-Codevasf | I2: e-Codevasf | J2: NI-027/2024 (fictícia) | K2: https://placehold.co/960x420/155bcb/ffffff?text=Diagrama+BPMN+A-06.01.01.01 | L2: Analista em Desenvolvimento Regional | M2: AR/GRB | N2: Registrar formalmente a necessidade da contratação, alinhada ao Plano de Contratações Anual.
A3: A-06.01.01.02 | B3: SP-06.01.01 | C3: 2 | D3: Levantar soluções de mercado | E3: Pesquisar soluções disponíveis, contratações similares e alternativas (inclusive não contratar). | F3: Equipe de planejamento da contratação | G3: DFD; Catálogos; Contratações similares (PNCP) | H3: Levantamento de soluções documentado | I3: PNCP; Compras.gov.br | J3: Lei nº 14.133/2021, art. 18 | L3: Técnico em Desenvolvimento Regional | M3: AA/GLC | N3: Identificar a solução mais adequada para atender à necessidade, considerando alternativas de mercado.
A4: A-06.01.01.03 | B4: SP-06.01.01 | C4: 3 | D4: Estimar quantidades e resultados | E4: Definir quantitativos com memória de cálculo e resultados pretendidos com a contratação. | F4: Equipe de planejamento da contratação | G4: Levantamento de soluções; Séries históricas | H4: Memória de cálculo de quantitativos | I4: e-Codevasf | J4: A definir | L4: Assistente em Desenvolvimento Regional | M4: AG/GGP | N4: Dimensionar com precisão os quantitativos e os resultados esperados da contratação.
A5: A-06.01.01.04 | B5: SP-06.01.01 | C5: 4 | D5: Elaborar e aprovar o ETP | E5: Consolidar o ETP no sistema e submeter à aprovação da autoridade competente. | F5: Equipe de planejamento; Autoridade competente | G5: Levantamentos e memórias anteriores | H5: ETP aprovado | I5: e-Codevasf; Compras.gov.br | J5: Lei nº 14.133/2021, art. 18 | L5: Analista em Desenvolvimento Regional | M5: AT/GTI | N5: Consolidar e submeter o Estudo Técnico Preliminar à aprovação da autoridade competente.
A6: A-06.01.02.01 | B6: SP-06.01.02 | C6: 1 | D6: Redigir o Termo de Referência | E6: Elaborar o TR a partir do ETP, definindo objeto, requisitos, modelo de execução e critérios de medição. | F6: Equipe de planejamento da contratação | G6: ETP aprovado; Modelos padronizados | H6: Minuta de TR | I6: e-Codevasf | J6: Lei nº 14.133/2021, art. 6º, XXIII | L6: Técnico em Desenvolvimento Regional | M6: AE/GPE | N6: Traduzir o ETP aprovado em um Termo de Referência claro e completo.
A7: A-06.01.02.02 | B7: SP-06.01.02 | C7: 2 | D7: Validar o TR com a Assessoria Jurídica | E7: Submeter a minuta ao órgão jurídico e ajustar conforme o parecer. | F7: AA/GLC; Assessoria Jurídica | G7: Minuta de TR | H7: TR validado; Parecer jurídico | I7: e-Codevasf | J7: Lei nº 14.133/2021, art. 53 | L7: Assistente em Desenvolvimento Regional | M7: AE/GAG | N7: Assegurar a conformidade jurídica do Termo de Referência antes da publicação.
A8: A-06.01.03.01 | B8: SP-06.01.03 | C8: 1 | D8: Realizar a pesquisa de preços | E8: Consultar fontes admitidas, registrar parâmetros e tratar valores inexequíveis ou excessivos. | F8: Equipe de planejamento da contratação | G8: TR validado; Fontes de preços | H8: Relatório de pesquisa de preços | I8: Painel de Preços; PNCP | J8: IN SEGES nº 65/2021 | L8: Analista em Desenvolvimento Regional | M8: AR/GDT | N8: Levantar parâmetros de preço confiáveis em fontes oficiais admitidas.
A9: A-06.01.03.02 | B9: SP-06.01.03 | C9: 2 | D9: Consolidar o valor estimado | E9: Aplicar o método definido (média/mediana/menor preço) e justificar a estimativa final. | F9: Equipe de planejamento da contratação | G9: Relatório de pesquisa | H9: Valor estimado consolidado | I9: e-Codevasf | J9: IN SEGES nº 65/2021, art. 6º | L9: Técnico em Desenvolvimento Regional | M9: AI/GOM | N9: Definir e justificar o valor estimado final da contratação.
A10: A-06.01.03.01.01 | B10: SP-06.01.03.01 | C10: 1 | D10: Aplicar critério de exclusão de valores discrepantes | E10: Comparar cada preço coletado à mediana da amostra e excluir, com justificativa registrada, os valores inexequíveis ou excessivos. | F10: Equipe de planejamento da contratação | G10: Amostra de preços coletados | H10: Amostra tratada; Justificativa de exclusão | I10: Planilha padrão | J10: IN SEGES nº 65/2021, art. 6º, §3º | L10: Assistente em Desenvolvimento Regional | M10: AR/GRB | N10: Evitar que preços inexequíveis ou excessivos distorçam a estimativa de valor.
A11: A-06.02.01.01 | B11: SP-06.02.01 | C11: 1 | D11: Publicar o edital | E11: Divulgar o edital no PNCP e no sistema de compras, observando prazos mínimos legais. | F11: Agente de contratação | G11: Edital aprovado; Parecer jurídico | H11: Edital publicado (PNCP) | I11: Compras.gov.br; PNCP | J11: Lei nº 14.133/2021, art. 54 | L11: Analista em Desenvolvimento Regional | M11: AA/GLC | N11: Dar publicidade ao certame, observando os prazos legais mínimos.
A12: A-06.02.01.02 | B12: SP-06.02.01 | C12: 2 | D12: Conduzir a sessão e julgar propostas | E12: Operar a fase de lances, julgar propostas, habilitar o vencedor e registrar a ata. | F12: Agente de contratação; Equipe de apoio | G12: Edital publicado; Propostas | H12: Ata da sessão; Resultado do julgamento | I12: Compras.gov.br | J12: Lei nº 14.133/2021 | L12: Técnico em Desenvolvimento Regional | M12: AG/GGP | N12: Selecionar a proposta mais vantajosa com transparência e celeridade.
A13: A-04.01.01.01 | B13: SP-04.01.01 | C13: 1 | D13: Programar a distribuição hídrica | E13: Elaborar a programação semanal de distribuição conforme demanda dos lotes e disponibilidade hídrica. | F13: Equipe de operação do perímetro | G13: Plano de cultivo; Disponibilidade hídrica | H13: Programação semanal aprovada | I13: SIG-Irrigação (fictício) | J13: A definir | L13: Assistente em Desenvolvimento Regional | M13: AT/GTI | N13: Equilibrar a demanda dos lotes com a disponibilidade hídrica do perímetro.
A14: A-04.01.01.02 | B14: SP-04.01.01 | C14: 2 | D14: Operar e registrar a distribuição | E14: Operar comportas e bombas conforme programação e registrar volumes por ponto de entrega. | F14: Equipe de operação do perímetro | G14: Programação semanal | H14: Volumes registrados; Ocorrências | I14: SIG-Irrigação (fictício) | J14: A definir | L14: Analista em Desenvolvimento Regional | M14: AE/GPE | N14: Executar a distribuição programada e manter o registro confiável dos volumes entregues.

Sheet Tarefas
A1: Codigo | B1: Atividade | C1: Ordem | D1: Nome | E1: Descricao | F1: Tipo_Tarefa | G1: Responsavel | H1: Sistema | I1: Duracao_Estimada | J1: Observacoes | K1: Imagem_Bizagi | L1: Unidades_Corresponsaveis
A2: T-06.01.01.01.01 | B2: A-06.01.01.01 | C2: 1 | D2: Reunir informações da demanda | E2: Levantar justificativa, quantitativos preliminares e alinhamento ao PCA junto ao gestor da área. | F2: Manual | G2: Área demandante | H2: e-Codevasf | I2: 4 | L2: AA/GLC
A3: T-06.01.01.01.02 | B3: A-06.01.01.01 | C3: 2 | D3: Preencher o formulário DFD no e-Codevasf | E3: Registrar o Documento de Formalização da Demanda no modelo padronizado. | F3: Manual | G3: Área demandante | H3: e-Codevasf | I3: 4 | J3: Modelo DOC-006/DOC-012. | L3: AG/GGP
A4: T-06.01.01.01.03 | B4: A-06.01.01.01 | C4: 3 | D4: Colher assinatura eletrônica do gestor | E4: Encaminhar o DFD para assinatura da autoridade competente da unidade. | F4: Manual | G4: Área demandante | H4: e-Codevasf | I4: 8 | L4: AT/GTI
A5: T-06.01.03.01.01 | B5: A-06.01.03.01 | C5: 1 | D5: Consultar o Painel de Preços | E5: Pesquisar contratações públicas similares e extrair os relatórios de preços. | F5: Manual | G5: Equipe de planejamento | H5: Painel de Preços | I5: 4 | L5: AE/GPE
A6: T-06.01.03.01.02 | B6: A-06.01.03.01 | C6: 2 | D6: Consultar contratações no PNCP | E6: Verificar atas e contratos vigentes de objetos equivalentes no PNCP. | F6: Manual | G6: Equipe de planejamento | H6: PNCP | I6: 4 | L6: AE/GAG
A7: T-06.01.03.01.03 | B7: A-06.01.03.01 | C7: 3 | D7: Registrar cotações de fornecedores | E7: Solicitar e registrar cotações diretas quando as fontes oficiais forem insuficientes. | F7: Manual | G7: Equipe de planejamento | H7: e-Codevasf | I7: 24 | J7: Mínimo de 3 fontes (IN 65/2021). | L7: AR/GDT
A8: T-06.01.03.01.04 | B8: A-06.01.03.01 | C8: 4 | D8: Aplicar tratamento estatístico | E8: Calcular média/mediana, excluir valores inexequíveis ou excessivos e justificar o método. | F8: Regra de negócio | G8: Equipe de planejamento | H8: Planilha padrão | I8: 4 | L8: AI/GOM
A9: T-06.02.01.01.01 | B9: A-06.02.01.01 | C9: 1 | D9: Cadastrar o edital no Compras.gov.br | E9: Inserir o edital aprovado, anexos e cronograma do certame no sistema. | F9: Manual | G9: Agente de contratação | H9: Compras.gov.br | I9: 4 | L9: AR/GRB
A10: T-06.02.01.01.02 | B10: A-06.02.01.01 | C10: 2 | D10: Publicar o aviso no PNCP | E10: Divulgação automática do aviso de licitação a partir do cadastro no sistema. | F10: Automatizada | G10: Compras.gov.br | H10: PNCP | I10: 0 | L10: AA/GLC
A11: T-04.01.01.01.01 | B11: A-04.01.01.01 | C11: 1 | D11: Consolidar demandas semanais dos lotes | E11: Compilar os pedidos de água dos irrigantes por setor hidráulico para a programação. | F11: Manual | G11: Equipe de operação | H11: SIG-Irrigação (fictício) | I11: 8 | L11: AG/GGP

Sheet Documentos
A1: ID | B1: Vinculo_Nivel | C1: Vinculo_Codigo | D1: Tipo_Documento | E1: Titulo | F1: Versao | G1: Data | H1: Situacao | I1: Link | J1: Observacoes
A2: DOC-001 | B2: =IF(C2="","",IF(LEFT(C2,3)="MP-","Macroprocesso",IF(LEFT(C2,3)="SP-","Subprocesso",IF(LEFT(C2,2)="P-","Processo",IF(LEFT(C2,2)="A-","Atividade",IF(LEFT(C2,2)="T-","Tarefa","")))))) -> Processo | C2: P-06.01 | D2: Procedimento (PRO) | E2: PRO 06.01 — Planejamento da Contratação | F2: 2.0 | G2: 2026-05-18 | H2: Vigente | I2: https://exemplo.codevasf.gov.br/repositorio/pop-06-01.pdf | J2: Publicado após validação do TO-BE.
A3: DOC-002 | B3: =IF(C3="","",IF(LEFT(C3,3)="MP-","Macroprocesso",IF(LEFT(C3,3)="SP-","Subprocesso",IF(LEFT(C3,2)="P-","Processo",IF(LEFT(C3,2)="A-","Atividade",IF(LEFT(C3,2)="T-","Tarefa","")))))) -> Processo | C3: P-06.01 | D3: Diagrama BPMN | E3: Diagrama AS-IS — Planejamento da Contratação (Bizagi) | F3: 1.0 | G3: 2026-03-02 | H3: Vigente | I3: https://fluxosti.codevasf.gov.br/incidentes/ | J3: Exportado do Bizagi Modeler. Mesmo link da ficha do processo (P-06.01).
A4: DOC-003 | B4: =IF(C4="","",IF(LEFT(C4,3)="MP-","Macroprocesso",IF(LEFT(C4,3)="SP-","Subprocesso",IF(LEFT(C4,2)="P-","Processo",IF(LEFT(C4,2)="A-","Atividade",IF(LEFT(C4,2)="T-","Tarefa","")))))) -> Processo | C4: P-06.01 | D4: Diagrama BPMN | E4: Diagrama TO-BE — Planejamento da Contratação (Bizagi) | F4: 1.0 | G4: 2026-05-04 | H4: Vigente | I4: https://exemplo.codevasf.gov.br/repositorio/p-06-01-tobe.pdf
A5: DOC-004 | B5: =IF(C5="","",IF(LEFT(C5,3)="MP-","Macroprocesso",IF(LEFT(C5,3)="SP-","Subprocesso",IF(LEFT(C5,2)="P-","Processo",IF(LEFT(C5,2)="A-","Atividade",IF(LEFT(C5,2)="T-","Tarefa","")))))) -> Processo | C5: P-06.01 | D5: Ata de reunião | E5: Ata — Reunião de contextualização com a GLC | F5: 1.0 | G5: 2026-01-12 | H5: Vigente | I5: https://exemplo.codevasf.gov.br/sei/ata-contextualizacao-p0601 | J5: e-Codevasf 59500.000123/2026-11.
A6: DOC-005 | B6: =IF(C6="","",IF(LEFT(C6,3)="MP-","Macroprocesso",IF(LEFT(C6,3)="SP-","Subprocesso",IF(LEFT(C6,2)="P-","Processo",IF(LEFT(C6,2)="A-","Atividade",IF(LEFT(C6,2)="T-","Tarefa","")))))) -> Processo | C6: P-06.01;SP-06.01.03 | D6: Relatório | E6: Relatório de oportunidades de melhoria (AS-IS → TO-BE) | F6: 1.0 | G6: 2026-04-13 | H6: Vigente | I6: https://exemplo.codevasf.gov.br/repositorio/rel-melhorias-p0601.pdf
A7: DOC-006 | B7: =IF(C7="","",IF(LEFT(C7,3)="MP-","Macroprocesso",IF(LEFT(C7,3)="SP-","Subprocesso",IF(LEFT(C7,2)="P-","Processo",IF(LEFT(C7,2)="A-","Atividade",IF(LEFT(C7,2)="T-","Tarefa","")))))) -> Subprocesso | C7: SP-06.01.01 | D7: Formulário/Modelo | E7: Modelo de DFD — Documento de Formalização da Demanda | F7: 3.1 | G7: 2026-02-10 | H7: Vigente | I7: https://exemplo.codevasf.gov.br/modelos/dfd.docx
A8: DOC-007 | B8: =IF(C8="","",IF(LEFT(C8,3)="MP-","Macroprocesso",IF(LEFT(C8,3)="SP-","Subprocesso",IF(LEFT(C8,2)="P-","Processo",IF(LEFT(C8,2)="A-","Atividade",IF(LEFT(C8,2)="T-","Tarefa","")))))) -> Subprocesso | C8: SP-06.01.03;SP-06.01.03.01 | D8: Procedimento (PRO) | E8: Roteiro de pesquisa de preços (IN SEGES nº 65/2021) | F8: 1.2 | G8: 2026-04-27 | H8: Vigente | I8: https://exemplo.codevasf.gov.br/repositorio/roteiro-precos.pdf
A9: DOC-008 | B9: =IF(C9="","",IF(LEFT(C9,3)="MP-","Macroprocesso",IF(LEFT(C9,3)="SP-","Subprocesso",IF(LEFT(C9,2)="P-","Processo",IF(LEFT(C9,2)="A-","Atividade",IF(LEFT(C9,2)="T-","Tarefa","")))))) -> Macroprocesso | C9: MP-06 | D9: Norma interna | E9: NI-027/2024 — Norma de Licitações e Contratos (fictícia) | F9: 4.0 | G9: 2024-11-20 | H9: Vigente | I9: https://exemplo.codevasf.gov.br/normativos/ni-027
A10: DOC-009 | B10: =IF(C10="","",IF(LEFT(C10,3)="MP-","Macroprocesso",IF(LEFT(C10,3)="SP-","Subprocesso",IF(LEFT(C10,2)="P-","Processo",IF(LEFT(C10,2)="A-","Atividade",IF(LEFT(C10,2)="T-","Tarefa","")))))) -> Processo | C10: P-06.01;P-06.03 | D10: Manual | E10: Manual de Gestão e Fiscalização de Contratos (fictício) | F10: 2.3 | G10: 2025-08-14 | H10: Em revisão | I10: https://exemplo.codevasf.gov.br/normativos/manual-fiscalizacao
A11: DOC-010 | B11: =IF(C11="","",IF(LEFT(C11,3)="MP-","Macroprocesso",IF(LEFT(C11,3)="SP-","Subprocesso",IF(LEFT(C11,2)="P-","Processo",IF(LEFT(C11,2)="A-","Atividade",IF(LEFT(C11,2)="T-","Tarefa","")))))) -> Processo | C11: P-06.02 | D11: Ata de reunião | E11: Ata — Contextualização do processo Seleção do Fornecedor | F11: 1.0 | G11: 2026-06-02 | H11: Vigente | I11: https://exemplo.codevasf.gov.br/sei/ata-contextualizacao-p0602
A12: DOC-011 | B12: =IF(C12="","",IF(LEFT(C12,3)="MP-","Macroprocesso",IF(LEFT(C12,3)="SP-","Subprocesso",IF(LEFT(C12,2)="P-","Processo",IF(LEFT(C12,2)="A-","Atividade",IF(LEFT(C12,2)="T-","Tarefa","")))))) -> Processo | C12: P-04.01 | D12: Diagrama BPMN | E12: Diagrama AS-IS parcial — O&M de Perímetros (Bizagi) | F12: 0.3 | G12: 2026-07-08 | H12: Em elaboração | J12: Modelagem em curso.
A13: DOC-012 | B13: =IF(C13="","",IF(LEFT(C13,3)="MP-","Macroprocesso",IF(LEFT(C13,3)="SP-","Subprocesso",IF(LEFT(C13,2)="P-","Processo",IF(LEFT(C13,2)="A-","Atividade",IF(LEFT(C13,2)="T-","Tarefa","")))))) -> Atividade | C13: A-06.01.01.01 | D13: Formulário/Modelo | E13: Passo a passo do DFD no e-Codevasf | F13: 1.0 | G13: 2026-02-12 | H13: Vigente | I13: https://exemplo.codevasf.gov.br/modelos/dfd-sei-passoapasso.pdf
A14: DOC-013 | B14: =IF(C14="","",IF(LEFT(C14,3)="MP-","Macroprocesso",IF(LEFT(C14,3)="SP-","Subprocesso",IF(LEFT(C14,2)="P-","Processo",IF(LEFT(C14,2)="A-","Atividade",IF(LEFT(C14,2)="T-","Tarefa","")))))) -> Processo | C14: P-01.01 | D14: Relatório | E14: Caderno de Indicadores Estratégicos 2026 | F14: 1.0 | G14: 2026-03-31 | H14: Vigente | I14: https://exemplo.codevasf.gov.br/estrategia/caderno-2026.pdf
A15: DOC-014 | B15: =IF(C15="","",IF(LEFT(C15,3)="MP-","Macroprocesso",IF(LEFT(C15,3)="SP-","Subprocesso",IF(LEFT(C15,2)="P-","Processo",IF(LEFT(C15,2)="A-","Atividade",IF(LEFT(C15,2)="T-","Tarefa","")))))) -> Processo | C15: P-06.01 | D15: Plano | E15: Plano de implantação do TO-BE (PMBOK — plano do projeto) | F15: 1.0 | G15: 2026-05-06 | H15: Vigente | I15: https://exemplo.codevasf.gov.br/repositorio/plano-tobe-p0601.pdf
A16: DOC-015 | B16: =IF(C16="","",IF(LEFT(C16,3)="MP-","Macroprocesso",IF(LEFT(C16,3)="SP-","Subprocesso",IF(LEFT(C16,2)="P-","Processo",IF(LEFT(C16,2)="A-","Atividade",IF(LEFT(C16,2)="T-","Tarefa","")))))) -> Processo | C16: P-06.01 | D16: Checklist | E16: Checklist de Conformidade — Planejamento da Contratação | F16: 1.0 | G16: 2026-05-18 | H16: Vigente | I16: https://exemplo.codevasf.gov.br/repositorio/checklist-p0601.pdf | J16: Exemplo — checklist ainda não padronizado para os demais processos da carteira.

Sheet Riscos
A1: ID | B1: Vinculo_Nivel | C1: Vinculo_Codigo | D1: Descricao_Risco | E1: Categoria | F1: Probabilidade_1a5 | G1: Impacto_1a5 | H1: Nivel_PxI | I1: Classificacao | J1: Resposta | K1: Controles_Tratamento | L1: Responsavel | M1: Status
A2: RIS-001 | B2: =IF(C2="","",IF(LEFT(C2,3)="MP-","Macroprocesso",IF(LEFT(C2,3)="SP-","Subprocesso",IF(LEFT(C2,2)="P-","Processo",IF(LEFT(C2,2)="A-","Atividade",IF(LEFT(C2,2)="T-","Tarefa","")))))) -> Processo | C2: P-06.01 | D2: Estimativas de preço defasadas gerando sobrepreço ou licitação deserta. | E2: Operacional | F2: 4 | G2: 4 | H2: =IF(OR(F2="",G2=""),"",F2*G2) -> 16 | I2: =IF(H2="","",IF(H2>=20,"Extremo",IF(H2>=12,"Alto",IF(H2>=5,"Moderado","Baixo")))) -> Alto | J2: Mitigar | K2: Roteiro de pesquisa com múltiplas fontes (Painel de Preços, PNCP) e revisão pela UNP. | L2: Ricardo Nogueira | M2: Em tratamento
A3: RIS-002 | B3: =IF(C3="","",IF(LEFT(C3,3)="MP-","Macroprocesso",IF(LEFT(C3,3)="SP-","Subprocesso",IF(LEFT(C3,2)="P-","Processo",IF(LEFT(C3,2)="A-","Atividade",IF(LEFT(C3,2)="T-","Tarefa","")))))) -> Processo | C3: P-06.01 | D3: TR genérico ou restritivo provocando impugnações e atrasos no certame. | E3: Legal/Conformidade | F3: 3 | G3: 4 | H3: =IF(OR(F3="",G3=""),"",F3*G3) -> 12 | I3: =IF(H3="","",IF(H3>=20,"Extremo",IF(H3>=12,"Alto",IF(H3>=5,"Moderado","Baixo")))) -> Alto | J3: Mitigar | K3: Checklist de revisão e validação obrigatória pela Assessoria Jurídica. | L3: Ricardo Nogueira | M3: Em tratamento
A4: RIS-003 | B4: =IF(C4="","",IF(LEFT(C4,3)="MP-","Macroprocesso",IF(LEFT(C4,3)="SP-","Subprocesso",IF(LEFT(C4,2)="P-","Processo",IF(LEFT(C4,2)="A-","Atividade",IF(LEFT(C4,2)="T-","Tarefa","")))))) -> Processo | C4: P-06.03 | D4: Fiscalização intempestiva de contratos, com medições e pagamentos atrasados. | E4: Operacional | F4: 3 | G4: 5 | H4: =IF(OR(F4="",G4=""),"",F4*G4) -> 15 | I4: =IF(H4="","",IF(H4>=20,"Extremo",IF(H4>=12,"Alto",IF(H4>=5,"Moderado","Baixo")))) -> Alto | J4: Mitigar | K4: Designação formal de fiscais, agenda de medições e alertas no e-Codevasf. | L4: Ricardo Nogueira | M4: Aberto
A5: RIS-004 | B5: =IF(C5="","",IF(LEFT(C5,3)="MP-","Macroprocesso",IF(LEFT(C5,3)="SP-","Subprocesso",IF(LEFT(C5,2)="P-","Processo",IF(LEFT(C5,2)="A-","Atividade",IF(LEFT(C5,2)="T-","Tarefa","")))))) -> Subprocesso | C5: SP-06.01.01 | D5: Conhecimento concentrado em um único empregado (pessoa-chave) na elaboração de ETP. | E5: Pessoas | F5: 4 | G5: 3 | H5: =IF(OR(F5="",G5=""),"",F5*G5) -> 12 | I5: =IF(H5="","",IF(H5>=20,"Extremo",IF(H5>=12,"Alto",IF(H5>=5,"Moderado","Baixo")))) -> Alto | J5: Mitigar | K5: Publicar o PRO, treinar substitutos e revezar a equipe de planejamento. | L5: Patrícia Ramos | M5: Em tratamento
A6: RIS-005 | B6: =IF(C6="","",IF(LEFT(C6,3)="MP-","Macroprocesso",IF(LEFT(C6,3)="SP-","Subprocesso",IF(LEFT(C6,2)="P-","Processo",IF(LEFT(C6,2)="A-","Atividade",IF(LEFT(C6,2)="T-","Tarefa","")))))) -> Processo | C6: P-04.01 | D6: Indisponibilidade hídrica comprometendo a programação de distribuição. | E6: Operacional | F6: 2 | G6: 5 | H6: =IF(OR(F6="",G6=""),"",F6*G6) -> 10 | I6: =IF(H6="","",IF(H6>=20,"Extremo",IF(H6>=12,"Alto",IF(H6>=5,"Moderado","Baixo")))) -> Moderado | J6: Mitigar | K6: Plano de contingência hídrica e priorização de culturas conforme regras do perímetro. | L6: Marcos Vinícius | M6: Aberto
A7: RIS-006 | B7: =IF(C7="","",IF(LEFT(C7,3)="MP-","Macroprocesso",IF(LEFT(C7,3)="SP-","Subprocesso",IF(LEFT(C7,2)="P-","Processo",IF(LEFT(C7,2)="A-","Atividade",IF(LEFT(C7,2)="T-","Tarefa","")))))) -> Processo | C7: P-06.02 | D7: Instabilidade do Compras.gov.br durante a sessão pública. | E7: Tecnologia da Informação | F7: 2 | G7: 4 | H7: =IF(OR(F7="",G7=""),"",F7*G7) -> 8 | I7: =IF(H7="","",IF(H7>=20,"Extremo",IF(H7>=12,"Alto",IF(H7>=5,"Moderado","Baixo")))) -> Moderado | J7: Mitigar | K7: Protocolo de suspensão formal da sessão e comunicação imediata aos licitantes. | L7: Daniela Ribeiro | M7: Aberto
A8: RIS-007 | B8: =IF(C8="","",IF(LEFT(C8,3)="MP-","Macroprocesso",IF(LEFT(C8,3)="SP-","Subprocesso",IF(LEFT(C8,2)="P-","Processo",IF(LEFT(C8,2)="A-","Atividade",IF(LEFT(C8,2)="T-","Tarefa","")))))) -> Macroprocesso | C8: MP-06 | D8: Alterações normativas frequentes exigindo atualização contínua de procedimentos. | E8: Legal/Conformidade | F8: 4 | G8: 2 | H8: =IF(OR(F8="",G8=""),"",F8*G8) -> 8 | I8: =IF(H8="","",IF(H8>=20,"Extremo",IF(H8>=12,"Alto",IF(H8>=5,"Moderado","Baixo")))) -> Moderado | J8: Mitigar | K8: Monitoramento normativo mensal (resenha) e revisão programada dos PROs. | L8: Bruna Souza | M8: Em tratamento
A9: RIS-008 | B9: =IF(C9="","",IF(LEFT(C9,3)="MP-","Macroprocesso",IF(LEFT(C9,3)="SP-","Subprocesso",IF(LEFT(C9,2)="P-","Processo",IF(LEFT(C9,2)="A-","Atividade",IF(LEFT(C9,2)="T-","Tarefa","")))))) -> Atividade | C9: A-06.01.03.01 | D9: Uso de fontes de preço não admitidas pela IN SEGES nº 65/2021. | E9: Legal/Conformidade | F9: 2 | G9: 3 | H9: =IF(OR(F9="",G9=""),"",F9*G9) -> 6 | I9: =IF(H9="","",IF(H9>=20,"Extremo",IF(H9>=12,"Alto",IF(H9>=5,"Moderado","Baixo")))) -> Moderado | J9: Mitigar | K9: Validação da pesquisa pela UNP antes da aprovação do valor estimado. | L9: Carlos Eduardo Lima | M9: Encerrado
A10: RIS-009 | B10: =IF(C10="","",IF(LEFT(C10,3)="MP-","Macroprocesso",IF(LEFT(C10,3)="SP-","Subprocesso",IF(LEFT(C10,2)="P-","Processo",IF(LEFT(C10,2)="A-","Atividade",IF(LEFT(C10,2)="T-","Tarefa","")))))) -> Processo | C10: P-06.01 | D10: Baixo engajamento das áreas demandantes no preenchimento do DFD. | E10: Pessoas | F10: 3 | G10: 3 | H10: =IF(OR(F10="",G10=""),"",F10*G10) -> 9 | I10: =IF(H10="","",IF(H10>=20,"Extremo",IF(H10>=12,"Alto",IF(H10>=5,"Moderado","Baixo")))) -> Moderado | J10: Mitigar | K10: Oficinas de capacitação e modelo simplificado de DFD no e-Codevasf. | L10: Bruna Souza | M10: Encerrado

Sheet Indicadores
A1: ID | B1: Vinculo_Nivel | C1: Vinculo_Codigo | D1: Nome | E1: Descricao_Formula | F1: Unidade | G1: Polaridade | H1: Meta | I1: Resultado_Atual | J1: Situacao | K1: Periodicidade | L1: Fonte | M1: Ultima_Medicao
A2: IND-001 | B2: =IF(C2="","",IF(LEFT(C2,3)="MP-","Macroprocesso",IF(LEFT(C2,3)="SP-","Subprocesso",IF(LEFT(C2,2)="P-","Processo",IF(LEFT(C2,2)="A-","Atividade",IF(LEFT(C2,2)="T-","Tarefa","")))))) -> Macroprocesso | C2: MP-06 | D2: Tempo médio do ciclo de contratação | E2: Média de dias entre o DFD e a homologação do certame. | F2: dias | G2: Menor melhor | H2: 120 | I2: 148 | J2: =IF(I2="","Sem medição",IF(H2="","Sem meta",IF(LEFT(G2,5)="Maior",IF(I2>=H2,"Meta atingida","Abaixo da meta"),IF(I2<=H2,"Meta atingida","Acima da meta")))) -> Acima da meta | K2: Trimestral | L2: Compras.gov.br | M2: 2026-06-30
A3: IND-002 | B3: =IF(C3="","",IF(LEFT(C3,3)="MP-","Macroprocesso",IF(LEFT(C3,3)="SP-","Subprocesso",IF(LEFT(C3,2)="P-","Processo",IF(LEFT(C3,2)="A-","Atividade",IF(LEFT(C3,2)="T-","Tarefa","")))))) -> Processo | C3: P-06.01 | D3: Prazo médio de elaboração do ETP | E3: Média de dias úteis entre o DFD e a aprovação do ETP. | F3: dias | G3: Menor melhor | H3: 30 | I3: 26 | J3: =IF(I3="","Sem medição",IF(H3="","Sem meta",IF(LEFT(G3,5)="Maior",IF(I3>=H3,"Meta atingida","Abaixo da meta"),IF(I3<=H3,"Meta atingida","Acima da meta")))) -> Meta atingida | K3: Mensal | L3: e-Codevasf | M3: 2026-06-30
A4: IND-003 | B4: =IF(C4="","",IF(LEFT(C4,3)="MP-","Macroprocesso",IF(LEFT(C4,3)="SP-","Subprocesso",IF(LEFT(C4,2)="P-","Processo",IF(LEFT(C4,2)="A-","Atividade",IF(LEFT(C4,2)="T-","Tarefa","")))))) -> Processo | C4: P-06.02 | D4: Impugnações por edital | E4: Nº médio de impugnações recebidas por edital publicado. | F4: nº | G4: Menor melhor | H4: 1 | I4: 0.8 | J4: =IF(I4="","Sem medição",IF(H4="","Sem meta",IF(LEFT(G4,5)="Maior",IF(I4>=H4,"Meta atingida","Abaixo da meta"),IF(I4<=H4,"Meta atingida","Acima da meta")))) -> Meta atingida | K4: Trimestral | L4: Compras.gov.br | M4: 2026-06-30
A5: IND-004 | B5: =IF(C5="","",IF(LEFT(C5,3)="MP-","Macroprocesso",IF(LEFT(C5,3)="SP-","Subprocesso",IF(LEFT(C5,2)="P-","Processo",IF(LEFT(C5,2)="A-","Atividade",IF(LEFT(C5,2)="T-","Tarefa","")))))) -> Processo | C5: P-06.03 | D5: Contratos com fiscal designado | E5: % de contratos vigentes com fiscal formalmente designado. | F5: % | G5: Maior melhor | H5: 100 | I5: 92 | J5: =IF(I5="","Sem medição",IF(H5="","Sem meta",IF(LEFT(G5,5)="Maior",IF(I5>=H5,"Meta atingida","Abaixo da meta"),IF(I5<=H5,"Meta atingida","Acima da meta")))) -> Abaixo da meta | K5: Mensal | L5: e-Codevasf | M5: 2026-06-30
A6: IND-005 | B6: =IF(C6="","",IF(LEFT(C6,3)="MP-","Macroprocesso",IF(LEFT(C6,3)="SP-","Subprocesso",IF(LEFT(C6,2)="P-","Processo",IF(LEFT(C6,2)="A-","Atividade",IF(LEFT(C6,2)="T-","Tarefa","")))))) -> Processo | C6: P-04.01 | D6: Eficiência no uso da água | E6: Relação % entre volume faturado e volume captado no perímetro. | F6: % | G6: Maior melhor | H6: 75 | I6: 71 | J6: =IF(I6="","Sem medição",IF(H6="","Sem meta",IF(LEFT(G6,5)="Maior",IF(I6>=H6,"Meta atingida","Abaixo da meta"),IF(I6<=H6,"Meta atingida","Acima da meta")))) -> Abaixo da meta | K6: Mensal | L6: SIG-Irrigação (fictício) | M6: 2026-06-30
A7: IND-006 | B7: =IF(C7="","",IF(LEFT(C7,3)="MP-","Macroprocesso",IF(LEFT(C7,3)="SP-","Subprocesso",IF(LEFT(C7,2)="P-","Processo",IF(LEFT(C7,2)="A-","Atividade",IF(LEFT(C7,2)="T-","Tarefa","")))))) -> Macroprocesso | C7: MP-06 | D7: Processos com mapeamento concluído | E7: % de processos do macroprocesso com marco M9 concluído. | F7: % | G7: Maior melhor | H7: 100 | I7: 33 | J7: =IF(I7="","Sem medição",IF(H7="","Sem meta",IF(LEFT(G7,5)="Maior",IF(I7>=H7,"Meta atingida","Abaixo da meta"),IF(I7<=H7,"Meta atingida","Acima da meta")))) -> Abaixo da meta | K7: Trimestral | L7: Painel de Processos | M7: 2026-06-30
A8: IND-007 | B8: =IF(C8="","",IF(LEFT(C8,3)="MP-","Macroprocesso",IF(LEFT(C8,3)="SP-","Subprocesso",IF(LEFT(C8,2)="P-","Processo",IF(LEFT(C8,2)="A-","Atividade",IF(LEFT(C8,2)="T-","Tarefa","")))))) -> Processo | C8: P-01.01 | D8: Ações estratégicas monitoradas no prazo | E8: % de ações do plano com status atualizado no ciclo. | F8: % | G8: Maior melhor | H8: 95 | I8: 97 | J8: =IF(I8="","Sem medição",IF(H8="","Sem meta",IF(LEFT(G8,5)="Maior",IF(I8>=H8,"Meta atingida","Abaixo da meta"),IF(I8<=H8,"Meta atingida","Acima da meta")))) -> Meta atingida | K8: Trimestral | L8: Painéis de BI | M8: 2026-06-30
A9: IND-008 | B9: =IF(C9="","",IF(LEFT(C9,3)="MP-","Macroprocesso",IF(LEFT(C9,3)="SP-","Subprocesso",IF(LEFT(C9,2)="P-","Processo",IF(LEFT(C9,2)="A-","Atividade",IF(LEFT(C9,2)="T-","Tarefa","")))))) -> Subprocesso | C9: SP-06.01.03 | D9: Pesquisas de preço com 3+ fontes | E9: % de pesquisas de preços com três ou mais fontes admitidas. | F9: % | G9: Maior melhor | H9: 100 | I9: 88 | J9: =IF(I9="","Sem medição",IF(H9="","Sem meta",IF(LEFT(G9,5)="Maior",IF(I9>=H9,"Meta atingida","Abaixo da meta"),IF(I9<=H9,"Meta atingida","Acima da meta")))) -> Abaixo da meta | K9: Mensal | L9: e-Codevasf | M9: 2026-06-30
A10: IND-009 | B10: =IF(C10="","",IF(LEFT(C10,3)="MP-","Macroprocesso",IF(LEFT(C10,3)="SP-","Subprocesso",IF(LEFT(C10,2)="P-","Processo",IF(LEFT(C10,2)="A-","Atividade",IF(LEFT(C10,2)="T-","Tarefa","")))))) -> Macroprocesso | C10: MP-05 | D10: Nascentes recuperadas no ano | E10: Nº de nascentes com recuperação concluída no exercício. | F10: nº | G10: Maior melhor | H10: 120 | J10: =IF(I10="","Sem medição",IF(H10="","Sem meta",IF(LEFT(G10,5)="Maior",IF(I10>=H10,"Meta atingida","Abaixo da meta"),IF(I10<=H10,"Meta atingida","Acima da meta")))) -> Sem medição | K10: Anual | L10: GeoPortal (fictício)

Sheet Jornada
A1: Ordem | B1: Fase | C1: Nome | D1: Duracao | E1: Objetivo | F1: Atividades_Chave | G1: Quem_Faz | H1: Entregaveis | I1: Sentimento_Usuario
A2: 1 | B2: Descobrir | C2: Escuta e contextualização | D2: 1–2 semanas | E2: Compreender a dor real, o contexto e as expectativas de quem executa e de quem se beneficia do processo. | F2: Reunião de sensibilização com a unidade demandante; Entrevistas semiestruturadas com executores e gestores; Aplicação do formulário de contextualização; Escuta ativa das partes interessadas (jornada empática) | G2: NUGEP; Interlocutor da área; Dono do processo | H2: Ata de reunião; Formulário preenchido; Mapa de partes interessadas | I2: Curiosidade e ansiedade: “por que estão olhando meu trabalho?”
A3: 2 | B3: Definir | C3: Delimitação de escopo | D3: 1 semana | E3: Traçar limites claros: onde começa, onde termina, quem participa e o que está fora do mapeamento. | F3: SIPOC preliminar (Fornecedores, Entradas, Processo, Saídas, Clientes); Identificação de sistemas e normativos aplicáveis; Definição de premissas, restrições e critérios de sucesso; Termo de abertura do projeto de mapeamento (PMBOK) | G3: Gerente do projeto; NUGEP | H3: Ficha do mapeamento publicada | I3: Segurança: “agora sei o que esperam de mim”
A4: 3 | B4: Desenvolver | C4: Modelagem AS-IS | D4: 2–4 semanas | E4: Fotografar o processo como ele é hoje, incluindo variações, filas, retrabalhos e workarounds. | F4: Workshops de modelagem com quem executa; Desenho BPMN no Bizagi (com anexação de evidências); Registro de hipóteses, dores e memória do mapeamento (no processo e-Codevasf/e-Codevasf); Identificação de riscos, gargalos e handoffs | G4: Equipe de mapeamento; Executores do processo | H4: Diagrama BPMN AS-IS; Lista de dores e riscos | I4: Reconhecimento: “alguém finalmente enxerga o que a gente vive”
A5: 4 | B5: Desenvolver | C5: Validação AS-IS | D5: 1 semana | E5: Confirmar com quem executa e com quem decide que o retrato do processo é fiel. | F5: Reunião de validação com donos e executores; Ajustes finos no BPMN e nos artefatos; Homologação formal do AS-IS | G5: Dono do processo; NUGEP | H5: AS-IS homologado e publicado no repositório | I5: Orgulho: “é isso que a gente faz”
A6: 5 | B6: Desenvolver | C6: Redesenho TO-BE | D6: 2–4 semanas | E6: Desenhar o processo desejado, eliminando desperdícios e melhorando a experiência de quem executa e de quem recebe. | F6: Análise de causas-raiz das dores identificadas; Ideação de melhorias com a equipe da área; Modelagem TO-BE (BPMN) e simulação de cenários; Definição de indicadores de desempenho e riscos residuais | G6: NUGEP; Área; Escritório de Riscos (2ª linha) | H6: Diagrama TO-BE; Indicadores; Plano de transição | I6: Esperança: “dá pra melhorar de verdade”
A7: 6 | B7: Entregar | C7: Publicação e transição | D7: 2 semanas | E7: Colocar o novo processo em operação com apoio, treinamento e comunicação clara. | F7: Publicação no repositório institucional de processos; Capacitação dos executores e multiplicadores; Atualização de normativos e do e-Codevasf; Lançamento do TO-BE | G7: Área responsável; NUGEP; Comunicação | H7: Processo publicado; Equipe capacitada; Comunicação institucional | I7: Confiança: “fui preparado para o novo jeito”
A8: 7 | B8: Evoluir | C8: Monitoramento e indicadores | D8: Contínuo | E8: Acompanhar o desempenho real do processo e a experiência de quem o executa e recebe. | F8: Coleta de indicadores (eficiência, eficácia, qualidade, satisfação); Monitoramento de riscos e controles (2ª linha); Escuta contínua da unidade e dos beneficiários | G8: Dono do processo; NUGEP; Escritório de Riscos | H8: Painel de indicadores; Radar de riscos atualizado | I8: Pertencimento: “meu trabalho é acompanhado e valorizado”
A9: 8 | B9: Evoluir | C9: Melhoria contínua | D9: Contínuo | E9: Fechar o ciclo: aprender, ajustar e reiniciar a jornada sempre que necessário (PDCA/CBOK 4.0). | F9: Retrospectivas periódicas com a área; Revisão do processo com base em dados e feedback; Abertura de novo ciclo de redesenho quando necessário | G9: NUGEP; Comunidade de prática BPM | H9: Novo ciclo de mapeamento ou ajustes incrementais | I9: Autonomia: “nosso processo é vivo, evolui com a gente”

Sheet Repositorio
A1: ID | B1: Categoria | C1: Fase_Ciclo | D1: Codigo | E1: Titulo | F1: Descricao | G1: Fonte | H1: Link | I1: Ordem
A2: REP-001 | B2: Documento oficial | D2: RES 031/2025 | E2: Metodologia de Gerenciamento de Processos da Codevasf | F2: Documento normativo que institui a metodologia corporativa de gerenciamento de processos (disponível na intranet/e-Codevasf). | G2: Codevasf | H2: https://intraplone.codevasf.gov.br/documentos_normativos_referencia/governanca-e-gestao/copy_of_planos/met_gerenciamento-processos_res-031_2025-01-08.pdf | I2: 1
A3: REP-002 | B3: Documento oficial | D3: RES 031/2025 | E3: Guia de Gerenciamento de Processos da Codevasf | F3: Guia prático que detalha etapas, papéis, artefatos e padrões do mapeamento (disponível na intranet/e-Codevasf). | G3: Codevasf | H3: https://intraplone.codevasf.gov.br/documentos_normativos_referencia/governanca-e-gestao/copy_of_planos/guia_gerenciamento-processos_res-031_2025-01-08.pdf | I3: 2
A4: REP-005 | B4: Template | C4: Desenho | E4: Modelo de Diagramas BPMN | F4: Template padrão para modelagem em BPMN 2.0 (pools, lanes, eventos, atividades e gateways), em formato Bizagi e draw.io. | G4: Codevasf | H4: https://exemplo.codevasf.gov.br/modelos/template-bpmn.bpm | I4: 5
A5: REP-006 | B5: Template | C5: Análise | E5: Roteiro de Reunião de Contextualização | F5: Guia para conduzir a reunião de contextualização: perguntas-guia, dinâmicas de elicitação e checklist de tópicos. | G5: Codevasf | H5: https://exemplo.codevasf.gov.br/modelos/roteiro-contextualizacao.docx | I5: 6
A6: REP-011 | B6: Instrumento | C6: Desenho | D6: BPMN-01 | E6: Checklist BPMN 2.0 (notação) | F6: Lista de verificação dos elementos mínimos para um diagrama BPMN aderente ao padrão. | G6: CBOK 4.0 | H6: https://exemplo.codevasf.gov.br/instrumentos/bpmn-01.docx | I6: 11
A7: REP-012 | B7: Instrumento | C7: Desenho | D7: RACI-01 | E7: Matriz RACI | F7: Atribui Responsável (R), Aprovador (A), Consultado (C) e Informado (I) por atividade. | G7: PMBOK | H7: https://exemplo.codevasf.gov.br/instrumentos/raci-01.xlsx | I7: 12
A8: REP-013 | B8: Instrumento | C8: Monitoramento | D8: KPI-01 | E8: Canvas de Indicador (KPI) | F8: Define nome, fórmula, fonte, meta, periodicidade e responsável de um indicador. | G8: Codevasf | H8: https://exemplo.codevasf.gov.br/instrumentos/kpi-01.docx | I8: 13
A9: REP-014 | B9: Instrumento | C9: Análise | D9: RISK-01 | E9: Registro de Riscos (ISO 31000) | F9: Identifica risco, causa, efeito, probabilidade, impacto, resposta e responsável. | G9: ISO 31000 | H9: https://exemplo.codevasf.gov.br/instrumentos/risk-01.xlsx | I9: 14
A10: REP-015 | B10: Instrumento | C10: Análise | D10: AS-IS-01 | E10: Roteiro de entrevista AS-IS | F10: Perguntas-guia para levantar o processo como ele é hoje com quem executa. | G10: CBOK 4.0 | H10: https://exemplo.codevasf.gov.br/instrumentos/as-is-01.docx | I10: 15
A11: REP-016 | B11: Instrumento | C11: Implementação | D11: TO-BE-01 | E11: Plano de transição AS-IS → TO-BE | F11: Compara o processo atual e o futuro e organiza as ações de migração. | G11: CBOK 4.0 | H11: https://exemplo.codevasf.gov.br/instrumentos/to-be-01.docx | I11: 16
A12: REP-017 | B12: Instrumento | C12: Refinamento | D12: MAT-01 | E12: Diagnóstico rápido de maturidade (PEMM) | F12: Autoavaliação em 5 dimensões: desenho, executores, dono, infraestrutura e indicadores. | G12: CBOK 4.0 | H12: https://exemplo.codevasf.gov.br/instrumentos/mat-01.xlsx | I12: 17
A13: REP-018 | B13: Ferramenta | C13: Desenho | E13: Bizagi Modeler | F13: Ferramenta gratuita de modelagem BPMN 2.0, recomendada pela UNP para os diagramas AS-IS e TO-BE. | G13: Bizagi | H13: https://www.bizagi.com/pt/plataforma/modeler | I13: 18
A14: REP-022 | B14: Referência | E14: BPM CBOK 4.0 — ABPMP International | F14: Guia de referência em gerenciamento de processos de negócio; padrão metodológico principal da UNP. | G14: ABPMP | H14: https://www.abpmp-br.org | I14: 22
A15: REP-033 | B15: Referência | E15: BPMN 2.0 — Business Process Model and Notation | F15: Especificação oficial da notação usada nos diagramas (Bizagi e demais ferramentas de modelagem): símbolos, semântica de execução e serialização XML. | G15: OMG (Object Management Group) | H15: https://www.omg.org/spec/BPMN/2.0/ | I15: 23
A16: REP-025 | B16: Template | C16: Análise | E16: Mapa de Partes Interessadas (modelo) | F16: Identifica e classifica stakeholders por interesse e influência, com estratégia de engajamento por grupo. | G16: PMBOK | H16: https://exemplo.codevasf.gov.br/modelos/mapa-partes-interessadas.xlsx | I16: 25

Sheet NUGEP
A1: Ordem | B1: Nome | C1: Papel | D1: Unidade_Sigla | E1: Unidade_Nome | F1: Email | G1: Telefone | H1: Foto | I1: Hierarquia
A2: 1 | B2: Ricardo Nunes Vasconcelos | C2: Gerente-Executivo da Área de Gestão Estratégica | D2: AE | E2: =IF(D2="","",IFERROR(VLOOKUP(D2,Listas!$V$2:$W$40,2,FALSE),"")) -> Área de Gestão Estratégica | F2: ricardo.vasconcelos@codevasf.gov.br | G2: (61) 2028-4400 | H2: https://randomuser.me/api/portraits/men/32.jpg | I2: 1
A3: 2 | B3: Patrícia Moreira Lopes | C3: Gerente de Planejamento Estratégico | D3: AE/GPE | E3: =IF(D3="","",IFERROR(VLOOKUP(D3,Listas!$V$2:$W$40,2,FALSE),"")) -> Gerência de Planejamento Estratégico | F3: patricia.lopes@codevasf.gov.br | G3: (61) 2028-4430 | H3: https://randomuser.me/api/portraits/women/68.jpg | I3: 2
A4: 3 | B4: Bruna Souza | C4: Coordenadora do NUGEP | D4: AE/GPE/UNP | E4: =IF(D4="","",IFERROR(VLOOKUP(D4,Listas!$V$2:$W$40,2,FALSE),"")) -> Unidade de Gestão Normativa e de Processos | F4: bruna.souza@codevasf.gov.br | G4: (61) 2028-4441 | H4: https://randomuser.me/api/portraits/women/44.jpg | I4: 3
A5: 4 | B5: Carlos Eduardo Lima | C5: Analista de Processos | D5: AE/GPE | E5: =IF(D5="","",IFERROR(VLOOKUP(D5,Listas!$V$2:$W$40,2,FALSE),"")) -> Gerência de Planejamento Estratégico | F5: carlos.lima@codevasf.gov.br | G5: (61) 2028-4442 | H5: https://randomuser.me/api/portraits/men/45.jpg | I5: 3
A6: 5 | B6: Daniela Ribeiro | C6: Especialista em BPM | D6: AT/GTI | E6: =IF(D6="","",IFERROR(VLOOKUP(D6,Listas!$V$2:$W$40,2,FALSE),"")) -> Gerência de Tecnologia da Informação | F6: daniela.ribeiro@codevasf.gov.br | G6: (61) 2028-4501 | H6: https://randomuser.me/api/portraits/women/12.jpg | I6: 3
A7: 6 | B7: Eduardo Martins | C7: Interlocutor de Processos Finalísticos | D7: AR/GPR | E7: =IF(D7="","",IFERROR(VLOOKUP(D7,Listas!$V$2:$W$40,2,FALSE),"")) -> Gerência de Projetos de Revitalização | F7: eduardo.martins@codevasf.gov.br | G7: (61) 2028-4612 | H7: https://randomuser.me/api/portraits/men/76.jpg | I7: 3
A8: 7 | B8: Fernanda Alves | C8: Analista de Riscos e Conformidade | D8: AE/GAG | E8: =IF(D8="","",IFERROR(VLOOKUP(D8,Listas!$V$2:$W$40,2,FALSE),"")) -> Gerência de Auditoria e Governança | F8: fernanda.alves@codevasf.gov.br | G8: (61) 2028-4380 | H8: https://randomuser.me/api/portraits/women/29.jpg | I8: 3
A9: 8 | B9: Gustavo Pereira | C9: Apoio Metodológico — PMBOK/CBOK | D9: AE/GPE/UNP | E9: =IF(D9="","",IFERROR(VLOOKUP(D9,Listas!$V$2:$W$40,2,FALSE),"")) -> Unidade de Gestão Normativa e de Processos | F9: gustavo.pereira@codevasf.gov.br | G9: (61) 2028-4443 | H9: https://randomuser.me/api/portraits/men/22.jpg | I9: 3
A10: 9 | B10: Juliana Tavares | C10: Analista de Processos | D10: AE/GPE/UNP | E10: =IF(D10="","",IFERROR(VLOOKUP(D10,Listas!$V$2:$W$40,2,FALSE),"")) -> Unidade de Gestão Normativa e de Processos | F10: juliana.tavares@codevasf.gov.br | G10: (61) 2028-4444 | H10: https://randomuser.me/api/portraits/women/8.jpg | I10: 3
A11: 10 | B11: Rafael Menezes | C11: Analista de Dados e Indicadores | D11: AE/GPE | E11: =IF(D11="","",IFERROR(VLOOKUP(D11,Listas!$V$2:$W$40,2,FALSE),"")) -> Gerência de Planejamento Estratégico | F11: rafael.menezes@codevasf.gov.br | G11: (61) 2028-4445 | H11: https://randomuser.me/api/portraits/men/54.jpg | I11: 3
A12: 11 | B12: Camila Duarte | C12: Interlocutora de Processos de Suporte | D12: AA/GLC | E12: =IF(D12="","",IFERROR(VLOOKUP(D12,Listas!$V$2:$W$40,2,FALSE),"")) -> Gerência de Licitações e Contratos | F12: camila.duarte@codevasf.gov.br | G12: (61) 2028-4520 | H12: https://randomuser.me/api/portraits/women/90.jpg | I12: 3
